Workbook

Sheet Official data
A1: Operator | B1: To include in ranking?
A2: {=_xlfn._xlws.SORT(_xlfn.UNIQUE(Summary!C2:C2363))} -> Ceske Drahy | B2: No (partial data) | D2: {=_xlfn._xlws.FILTER(_xlfn.ANCHORARRAY(A2),B2:B28="yes")} -> DB | E2: done
A3: CFL | B3: No (partial data) | D3: Eurostar | E3: done
A4: CFR | B4: No (partial data) | D4: Flixtrain | E4: no official data
A5: DB | B5: Yes | D5: NS | E5: done (but they do pax pctlity)
A6: DSB | B6: No (partial data) | D6: OEBB | E6: done
A7: European Sleeper | B7: No (night train) | D7: Ouigo | E7: done
A8: Eurostar | B8: Yes | D8: SBB | E8: done
A9: Flixtrain | B9: Yes | D9: SNCB | E9: done
A10: HZ | B10: No (partial data) | D10: SNCF | E10: done
A11: MAV | B11: No (partial data) | D11: Trenitalia
A12: NS | B12: Yes | D12: Trenitalia France
A13: OEBB | B13: Yes | D13: Westbahn
A14: Other CH operators | B14: No (out of scope)
A15: Ouigo | B15: Yes
A16: Panorama Express | B16: No (out of scope)
A17: PKP | B17: No (partial data)
A18: SBB | B18: Yes
A19: SJ | B19: No (partial data)
A20: SNCB | B20: Yes
A21: SNCF | B21: Yes
A22: SZ | B22: No (partial data)
A23: Trenitalia | B23: Yes
A24: Trenitalia France | B24: Yes
A25: UNKNOWN_OPERATOR | B25: NAN
... A28: ZSSK | B28: No (partial data)

Sheet Pivot table
A2: Journey type | B2: (Multiple Items)
A3: Long distance | B3: Yes
L4: Sum of N train delay (> 3 min) | M4: Sum of N train delay (> 5 min) | N4: Sum of N train delay (> 6 min) | O4: Sum of N train delay (> 10 min) | P4: Sum of N train delay (> 15 min) | Q4: Sum of N train delay (> 30 min) | R4: Sum of N train delay (> 60 min)
A5: Row Labels | B5: Sum of N total train | C5: Sum of N cancelled train (full + partial) | D5: Sum of N train delay (> 3 min) | E5: Sum of N train delay (> 5 min) | F5: Sum of N train delay (> 6 min) | G5: Sum of N train delay (> 10 min) | H5: Sum of N train delay (> 15 min) | I5: Sum of N train delay (> 30 min) | J5: Sum of N train delay (> 60 min) | K5: Cancellation rate | L5: Reliability 3min | M5: Reliability 5min | N5: Reliability 6min | O5: Reliability 10min | P5: Reliability 15min | Q5: Reliability 30min | R5: Reliability 60min
A6: Ceske Drahy | B6: 9380 | C6: 21 | D6: 2707 | E6: 2385 | F6: 2246 | G6: 1740 | H6: 1355 | I6: 720 | J6: 280 | K6: =GETPIVOTDATA("Sum of N cancelled train (full + partial)",$A$5,"operator",$A6)/GETPIVOTDATA("Sum of N total train",$A$5,"operator",$A6) -> 0.002238806 | L6: =1-(GETPIVOTDATA("Sum of N cancelled train (full + partial)",$A$5,"operator",$A6)+GETPIVOTDATA(L$4&"",$A$5,"operator",$A6))/GETPIVOTDATA("Sum of N total train",$A$5,"operator",$A6) -> 0.70916844 | M6: =1-(GETPIVOTDATA("Sum of N cancelled train (full + partial)",$A$5,"operator",$A6)+GETPIVOTDATA(M$4&"",$A$5,"operator",$A6))/GETPIVOTDATA("Sum of N total train",$A$5,"operator",$A6) -> 0.7434968 | N6: =1-(GETPIVOTDATA("Sum of N cancelled train (full + partial)",$A$5,"operator",$A6)+GETPIVOTDATA(N$4&"",$A$5,"operator",$A6))/GETPIVOTDATA("Sum of N total train",$A$5,"operator",$A6) -> 0.75831557 | O6: =1-(GETPIVOTDATA("Sum of N cancelled train (full + partial)",$A$5,"operator",$A6)+GETPIVOTDATA(O$4&"",$A$5,"operator",$A6))/GETPIVOTDATA("Sum of N total train",$A$5,"operator",$A6) -> 0.81226013 | P6: =1-(GETPIVOTDATA("Sum of N cancelled train (full + partial)",$A$5,"operator",$A6)+GETPIVOTDATA(P$4&"",$A$5,"operator",$A6))/GETPIVOTDATA("Sum of N total train",$A$5,"operator",$A6) -> 0.8533049 | Q6: =1-(GETPIVOTDATA("Sum of N cancelled train (full + partial)",$A$5,"operator",$A6)+GETPIVOTDATA(Q$4&"",$A$5,"operator",$A6))/GETPIVOTDATA("Sum of N total train",$A$5,"operator",$A6) -> 0.92100213 | R6: =1-(GETPIVOTDATA("Sum of N cancelled train (full + partial)",$A$5,"operator",$A6)+GETPIVOTDATA(R$4&"",$A$5,"operator",$A6))/GETPIVOTDATA("Sum of N total train",$A$5,"operator",$A6) -> 0.96791045
A7: CFL | B7: 14719 | C7: 180 | D7: 1742 | E7: 958 | F7: 791 | G7: 502 | H7: 323 | I7: 106 | J7: 15 | K7: =GETPIVOTDATA("Sum of N cancelled train (full + partial)",$A$5,"operator",$A7)/GETPIVOTDATA("Sum of N total train",$A$5,"operator",$A7) -> 0.012229092 | L7: =1-(GETPIVOTDATA("Sum of N cancelled train (full + partial)",$A$5,"operator",$A7)+GETPIVOTDATA(L$4&"",$A$5,"operator",$A7))/GETPIVOTDATA("Sum of N total train",$A$5,"operator",$A7) -> 0.86942048 | M7: =1-(GETPIVOTDATA("Sum of N cancelled train (full + partial)",$A$5,"operator",$A7)+GETPIVOTDATA(M$4&"",$A$5,"operator",$A7))/GETPIVOTDATA("Sum of N total train",$A$5,"operator",$A7) -> 0.92268497 | N7: =1-(GETPIVOTDATA("Sum of N cancelled train (full + partial)",$A$5,"operator",$A7)+GETPIVOTDATA(N$4&"",$A$5,"operator",$A7))/GETPIVOTDATA("Sum of N total train",$A$5,"operator",$A7) -> 0.93403084 | O7: =1-(GETPIVOTDATA("Sum of N cancelled train (full + partial)",$A$5,"operator",$A7)+GETPIVOTDATA(O$4&"",$A$5,"operator",$A7))/GETPIVOTDATA("Sum of N total train",$A$5,"operator",$A7) -> 0.95366533 | P7: =1-(GETPIVOTDATA("Sum of N cancelled train (full + partial)",$A$5,"operator",$A7)+GETPIVOTDATA(P$4&"",$A$5,"operator",$A7))/GETPIVOTDATA("Sum of N total train",$A$5,"operator",$A7) -> 0.96582648 | Q7: =1-(GETPIVOTDATA("Sum of N cancelled train (full + partial)",$A$5,"operator",$A7)+GETPIVOTDATA(Q$4&"",$A$5,"operator",$A7))/GETPIVOTDATA("Sum of N total train",$A$5,"operator",$A7) -> 0.98056933 | R7: =1-(GETPIVOTDATA("Sum of N cancelled train (full + partial)",$A$5,"operator",$A7)+GETPIVOTDATA(R$4&"",$A$5,"operator",$A7))/GETPIVOTDATA("Sum of N total train",$A$5,"operator",$A7) -> 0.98675182
A8: CFR | B8: 7 | C8: 0 | D8: 0 | E8: 0 | F8: 0 | G8: 0 | H8: 0 | I8: 0 | J8: 0 | K8: =GETPIVOTDATA("Sum of N cancelled train (full + partial)",$A$5,"operator",$A8)/GETPIVOTDATA("Sum of N total train",$A$5,"operator",$A8) -> 0 | L8: =1-(GETPIVOTDATA("Sum of N cancelled train (full + partial)",$A$5,"operator",$A8)+GETPIVOTDATA(L$4&"",$A$5,"operator",$A8))/GETPIVOTDATA("Sum of N total train",$A$5,"operator",$A8) -> 1 | M8: =1-(GETPIVOTDATA("Sum of N cancelled train (full + partial)",$A$5,"operator",$A8)+GETPIVOTDATA(M$4&"",$A$5,"operator",$A8))/GETPIVOTDATA("Sum of N total train",$A$5,"operator",$A8) -> 1 | N8: =1-(GETPIVOTDATA("Sum of N cancelled train (full + partial)",$A$5,"operator",$A8)+GETPIVOTDATA(N$4&"",$A$5,"operator",$A8))/GETPIVOTDATA("Sum of N total train",$A$5,"operator",$A8) -> 1 | O8: =1-(GETPIVOTDATA("Sum of N cancelled train (full + partial)",$A$5,"operator",$A8)+GETPIVOTDATA(O$4&"",$A$5,"operator",$A8))/GETPIVOTDATA("Sum of N total train",$A$5,"operator",$A8) -> 1 | P8: =1-(GETPIVOTDATA("Sum of N cancelled train (full + partial)",$A$5,"operator",$A8)+GETPIVOTDATA(P$4&"",$A$5,"operator",$A8))/GETPIVOTDATA("Sum of N total train",$A$5,"operator",$A8) -> 1 | Q8: =1-(GETPIVOTDATA("Sum of N cancelled train (full + partial)",$A$5,"operator",$A8)+GETPIVOTDATA(Q$4&"",$A$5,"operator",$A8))/GETPIVOTDATA("Sum of N total train",$A$5,"operator",$A8) -> 1 | R8: =1-(GETPIVOTDATA("Sum of N cancelled train (full + partial)",$A$5,"operator",$A8)+GETPIVOTDATA(R$4&"",$A$5,"operator",$A8))/GETPIVOTDATA("Sum of N total train",$A$5,"operator",$A8) -> 1
A9: DB | B9: 345877 | C9: 37629 | D9: 196709 | E9: 169753 | F9: 159285 | G9: 126488 | H9: 98685 | I9: 50551 | J9: 15923 | K9: =GETPIVOTDATA("Sum of N cancelled train (full + partial)",$A$5,"operator",$A9)/GETPIVOTDATA("Sum of N total train",$A$5,"operator",$A9) -> 0.10879301 | L9: =1-(GETPIVOTDATA("Sum of N cancelled train (full + partial)",$A$5,"operator",$A9)+GETPIVOTDATA(L$4&"",$A$5,"operator",$A9))/GETPIVOTDATA("Sum of N total train",$A$5,"operator",$A9) -> 0.32248169 | M9: =1-(GETPIVOTDATA("Sum of N cancelled train (full + partial)",$A$5,"operator",$A9)+GETPIVOTDATA(M$4&"",$A$5,"operator",$A9))/GETPIVOTDATA("Sum of N total train",$A$5,"operator",$A9) -> 0.40041691 | N9: =1-(GETPIVOTDATA("Sum of N cancelled train (full + partial)",$A$5,"operator",$A9)+GETPIVOTDATA(N$4&"",$A$5,"operator",$A9))/GETPIVOTDATA("Sum of N total train",$A$5,"operator",$A9) -> 0.43068201 | O9: =1-(GETPIVOTDATA("Sum of N cancelled train (full + partial)",$A$5,"operator",$A9)+GETPIVOTDATA(O$4&"",$A$5,"operator",$A9))/GETPIVOTDATA("Sum of N total train",$A$5,"operator",$A9) -> 0.52550473 | P9: =1-(GETPIVOTDATA("Sum of N cancelled train (full + partial)",$A$5,"operator",$A9)+GETPIVOTDATA(P$4&"",$A$5,"operator",$A9))/GETPIVOTDATA("Sum of N total train",$A$5,"operator",$A9) -> 0.6058888 | Q9: =1-(GETPIVOTDATA("Sum of N cancelled train (full + partial)",$A$5,"operator",$A9)+GETPIVOTDATA(Q$4&"",$A$5,"operator",$A9))/GETPIVOTDATA("Sum of N total train",$A$5,"operator",$A9) -> 0.74505388 | R9: =1-(GETPIVOTDATA("Sum of N cancelled train (full + partial)",$A$5,"operator",$A9)+GETPIVOTDATA(R$4&"",$A$5,"operator",$A9))/GETPIVOTDATA("Sum of N total train",$A$5,"operator",$A9) -> 0.84517039
A10: DSB | B10: 5903 | C10: 48 | D10: 1397 | E10: 904 | F10: 781 | G10: 500 | H10: 351 | I10: 190 | J10: 105 | K10: =GETPIVOTDATA("Sum of N cancelled train (full + partial)",$A$5,"operator",$A10)/GETPIVOTDATA("Sum of N total train",$A$5,"operator",$A10) -> 0.0081314586 | L10: =1-(GETPIVOTDATA("Sum of N cancelled train (full + partial)",$A$5,"operator",$A10)+GETPIVOTDATA(L$4&"",$A$5,"operator",$A10))/GETPIVOTDATA("Sum of N total train",$A$5,"operator",$A10) -> 0.75520922 | M10: =1-(GETPIVOTDATA("Sum of N cancelled train (full + partial)",$A$5,"operator",$A10)+GETPIVOTDATA(M$4&"",$A$5,"operator",$A10))/GETPIVOTDATA("Sum of N total train",$A$5,"operator",$A10) -> 0.83872607 | N10: =1-(GETPIVOTDATA("Sum of N cancelled train (full + partial)",$A$5,"operator",$A10)+GETPIVOTDATA(N$4&"",$A$5,"operator",$A10))/GETPIVOTDATA("Sum of N total train",$A$5,"operator",$A10) -> 0.85956293 | O10: =1-(GETPIVOTDATA("Sum of N cancelled train (full + partial)",$A$5,"operator",$A10)+GETPIVOTDATA(O$4&"",$A$5,"operator",$A10))/GETPIVOTDATA("Sum of N total train",$A$5,"operator",$A10) -> 0.90716585 | P10: =1-(GETPIVOTDATA("Sum of N cancelled train (full + partial)",$A$5,"operator",$A10)+GETPIVOTDATA(P$4&"",$A$5,"operator",$A10))/GETPIVOTDATA("Sum of N total train",$A$5,"operator",$A10) -> 0.93240725 | Q10: =1-(GETPIVOTDATA("Sum of N cancelled train (full + partial)",$A$5,"operator",$A10)+GETPIVOTDATA(Q$4&"",$A$5,"operator",$A10))/GETPIVOTDATA("Sum of N total train",$A$5,"operator",$A10) -> 0.95968152 | R10: =1-(GETPIVOTDATA("Sum of N cancelled train (full + partial)",$A$5,"operator",$A10)+GETPIVOTDATA(R$4&"",$A$5,"operator",$A10))/GETPIVOTDATA("Sum of N total train",$A$5,"operator",$A10) -> 0.97408098
A11: European Sleeper | B11: 308 | C11: 28 | D11: 121 | E11: 114 | F11: 107 | G11: 97 | H11: 83 | I11: 63 | J11: 28 | K11: =GETPIVOTDATA("Sum of N cancelled train (full + partial)",$A$5,"operator",$A11)/GETPIVOTDATA("Sum of N total train",$A$5,"operator",$A11) -> 0.090909091 | L11: =1-(GETPIVOTDATA("Sum of N cancelled train (full + partial)",$A$5,"operator",$A11)+GETPIVOTDATA(L$4&"",$A$5,"operator",$A11))/GETPIVOTDATA("Sum of N total train",$A$5,"operator",$A11) -> 0.51623377 | M11: =1-(GETPIVOTDATA("Sum of N cancelled train (full + partial)",$A$5,"operator",$A11)+GETPIVOTDATA(M$4&"",$A$5,"operator",$A11))/GETPIVOTDATA("Sum of N total train",$A$5,"operator",$A11) -> 0.53896104 | N11: =1-(GETPIVOTDATA("Sum of N cancelled train (full + partial)",$A$5,"operator",$A11)+GETPIVOTDATA(N$4&"",$A$5,"operator",$A11))/GETPIVOTDATA("Sum of N total train",$A$5,"operator",$A11) -> 0.56168831 | O11: =1-(GETPIVOTDATA("Sum of N cancelled train (full + partial)",$A$5,"operator",$A11)+GETPIVOTDATA(O$4&"",$A$5,"operator",$A11))/GETPIVOTDATA("Sum of N total train",$A$5,"operator",$A11) -> 0.59415584 | P11: =1-(GETPIVOTDATA("Sum of N cancelled train (full + partial)",$A$5,"operator",$A11)+GETPIVOTDATA(P$4&"",$A$5,"operator",$A11))/GETPIVOTDATA("Sum of N total train",$A$5,"operator",$A11) -> 0.63961039 | Q11: =1-(GETPIVOTDATA("Sum of N cancelled train (full + partial)",$A$5,"operator",$A11)+GETPIVOTDATA(Q$4&"",$A$5,"operator",$A11))/GETPIVOTDATA("Sum of N total train",$A$5,"operator",$A11) -> 0.70454545 | R11: =1-(GETPIVOTDATA("Sum of N cancelled train (full + partial)",$A$5,"operator",$A11)+GETPIVOTDATA(R$4&"",$A$5,"operator",$A11))/GETPIVOTDATA("Sum of N total train",$A$5,"operator",$A11) -> 0.81818182
A12: Eurostar | B12: 42665 | C12: 4389 | D12: 11014 | E12: 10840 | F12: 10763 | G12: 8043 | H12: 6451 | I12: 3044 | J12: 1068 | K12: =GETPIVOTDATA("Sum of N cancelled train (full + partial)",$A$5,"operator",$A12)/GETPIVOTDATA("Sum of N total train",$A$5,"operator",$A12) -> 0.10287121 | L12: =1-(GETPIVOTDATA("Sum of N cancelled train (full + partial)",$A$5,"operator",$A12)+GETPIVOTDATA(L$4&"",$A$5,"operator",$A12))/GETPIVOTDATA("Sum of N total train",$A$5,"operator",$A12) -> 0.63897809 | M12: =1-(GETPIVOTDATA("Sum of N cancelled train (full + partial)",$A$5,"operator",$A12)+GETPIVOTDATA(M$4&"",$A$5,"operator",$A12))/GETPIVOTDATA("Sum of N total train",$A$5,"operator",$A12) -> 0.64305637 | N12: =1-(GETPIVOTDATA("Sum of N cancelled train (full + partial)",$A$5,"operator",$A12)+GETPIVOTDATA(N$4&"",$A$5,"operator",$A12))/GETPIVOTDATA("Sum of N total train",$A$5,"operator",$A12) -> 0.64486113 | O12: =1-(GETPIVOTDATA("Sum of N cancelled train (full + partial)",$A$5,"operator",$A12)+GETPIVOTDATA(O$4&"",$A$5,"operator",$A12))/GETPIVOTDATA("Sum of N total train",$A$5,"operator",$A12) -> 0.70861362 | P12: =1-(GETPIVOTDATA("Sum of N cancelled train (full + partial)",$A$5,"operator",$A12)+GETPIVOTDATA(P$4&"",$A$5,"operator",$A12))/GETPIVOTDATA("Sum of N total train",$A$5,"operator",$A12) -> 0.74592758 | Q12: =1-(GETPIVOTDATA("Sum of N cancelled train (full + partial)",$A$5,"operator",$A12)+GETPIVOTDATA(Q$4&"",$A$5,"operator",$A12))/GETPIVOTDATA("Sum of N total train",$A$5,"operator",$A12) -> 0.82578226 | R12: =1-(GETPIVOTDATA("Sum of N cancelled train (full + partial)",$A$5,"operator",$A12)+GETPIVOTDATA(R$4&"",$A$5,"operator",$A12))/GETPIVOTDATA("Sum of N total train",$A$5,"operator",$A12) -> 0.87209657
A13: Flixtrain | B13: 6229 | C13: 476 | D13: 4043 | E13: 3615 | F13: 3453 | G13: 2844 | H13: 2336 | I13: 1363 | J13: 542 | K13: =GETPIVOTDATA("Sum of N cancelled train (full + partial)",$A$5,"operator",$A13)/GETPIVOTDATA("Sum of N total train",$A$5,"operator",$A13) -> 0.07641676 | L13: =1-(GETPIVOTDATA("Sum of N cancelled train (full + partial)",$A$5,"operator",$A13)+GETPIVOTDATA(L$4&"",$A$5,"operator",$A13))/GETPIVOTDATA("Sum of N total train",$A$5,"operator",$A13) -> 0.2745224 | M13: =1-(GETPIVOTDATA("Sum of N cancelled train (full + partial)",$A$5,"operator",$A13)+GETPIVOTDATA(M$4&"",$A$5,"operator",$A13))/GETPIVOTDATA("Sum of N total train",$A$5,"operator",$A13) -> 0.34323326 | N13: =1-(GETPIVOTDATA("Sum of N cancelled train (full + partial)",$A$5,"operator",$A13)+GETPIVOTDATA(N$4&"",$A$5,"operator",$A13))/GETPIVOTDATA("Sum of N total train",$A$5,"operator",$A13) -> 0.36924065 | O13: =1-(GETPIVOTDATA("Sum of N cancelled train (full + partial)",$A$5,"operator",$A13)+GETPIVOTDATA(O$4&"",$A$5,"operator",$A13))/GETPIVOTDATA("Sum of N total train",$A$5,"operator",$A13) -> 0.46700915 | P13: =1-(GETPIVOTDATA("Sum of N cancelled train (full + partial)",$A$5,"operator",$A13)+GETPIVOTDATA(P$4&"",$A$5,"operator",$A13))/GETPIVOTDATA("Sum of N total train",$A$5,"operator",$A13) -> 0.54856317 | Q13: =1-(GETPIVOTDATA("Sum of N cancelled train (full + partial)",$A$5,"operator",$A13)+GETPIVOTDATA(Q$4&"",$A$5,"operator",$A13))/GETPIVOTDATA("Sum of N total train",$A$5,"operator",$A13) -> 0.70476802 | R13: =1-(GETPIVOTDATA("Sum of N cancelled train (full + partial)",$A$5,"operator",$A13)+GETPIVOTDATA(R$4&"",$A$5,"operator",$A13))/GETPIVOTDATA("Sum of N total train",$A$5,"operator",$A13) -> 0.83657088
A14: HZ | B14: 1411 | C14: 11 | D14: 88 | E14: 61 | F14: 54 | G14: 45 | H14: 29 | I14: 23 | J14: 9 | K14: =GETPIVOTDATA("Sum of N cancelled train (full + partial)",$A$5,"operator",$A14)/GETPIVOTDATA("Sum of N total train",$A$5,"operator",$A14) -> 0.0077958894 | L14: =1-(GETPIVOTDATA("Sum of N cancelled train (full + partial)",$A$5,"operator",$A14)+GETPIVOTDATA(L$4&"",$A$5,"operator",$A14))/GETPIVOTDATA("Sum of N total train",$A$5,"operator",$A14) -> 0.929837 | M14: =1-(GETPIVOTDATA("Sum of N cancelled train (full + partial)",$A$5,"operator",$A14)+GETPIVOTDATA(M$4&"",$A$5,"operator",$A14))/GETPIVOTDATA("Sum of N total train",$A$5,"operator",$A14) -> 0.94897236 | N14: =1-(GETPIVOTDATA("Sum of N cancelled train (full + partial)",$A$5,"operator",$A14)+GETPIVOTDATA(N$4&"",$A$5,"operator",$A14))/GETPIVOTDATA("Sum of N total train",$A$5,"operator",$A14) -> 0.95393338 | O14: =1-(GETPIVOTDATA("Sum of N cancelled train (full + partial)",$A$5,"operator",$A14)+GETPIVOTDATA(O$4&"",$A$5,"operator",$A14))/GETPIVOTDATA("Sum of N total train",$A$5,"operator",$A14) -> 0.96031184 | P14: =1-(GETPIVOTDATA("Sum of N cancelled train (full + partial)",$A$5,"operator",$A14)+GETPIVOTDATA(P$4&"",$A$5,"operator",$A14))/GETPIVOTDATA("Sum of N total train",$A$5,"operator",$A14) -> 0.97165131 | Q14: =1-(GETPIVOTDATA("Sum of N cancelled train (full + partial)",$A$5,"operator",$A14)+GETPIVOTDATA(Q$4&"",$A$5,"operator",$A14))/GETPIVOTDATA("Sum of N total train",$A$5,"operator",$A14) -> 0.97590361 | R14: =1-(GETPIVOTDATA("Sum of N cancelled train (full + partial)",$A$5,"operator",$A14)+GETPIVOTDATA(R$4&"",$A$5,"operator",$A14))/GETPIVOTDATA("Sum of N total train",$A$5,"operator",$A14) -> 0.98582566
A15: MAV | B15: 16353 | C15: 17 | D15: 3409 | E15: 2988 | F15: 2774 | G15: 2110 | H15: 1574 | I15: 740 | J15: 200 | K15: =GETPIVOTDATA("Sum of N cancelled train (full + partial)",$A$5,"operator",$A15)/GETPIVOTDATA("Sum of N total train",$A$5,"operator",$A15) -> 0.0010395646 | L15: =1-(GETPIVOTDATA("Sum of N cancelled train (full + partial)",$A$5,"operator",$A15)+GETPIVOTDATA(L$4&"",$A$5,"operator",$A15))/GETPIVOTDATA("Sum of N total train",$A$5,"operator",$A15) -> 0.79049716 | M15: =1-(GETPIVOTDATA("Sum of N cancelled train (full + partial)",$A$5,"operator",$A15)+GETPIVOTDATA(M$4&"",$A$5,"operator",$A15))/GETPIVOTDATA("Sum of N total train",$A$5,"operator",$A15) -> 0.81624167 | N15: =1-(GETPIVOTDATA("Sum of N cancelled train (full + partial)",$A$5,"operator",$A15)+GETPIVOTDATA(N$4&"",$A$5,"operator",$A15))/GETPIVOTDATA("Sum of N total train",$A$5,"operator",$A15) -> 0.82932795 | O15: =1-(GETPIVOTDATA("Sum of N cancelled train (full + partial)",$A$5,"operator",$A15)+GETPIVOTDATA(O$4&"",$A$5,"operator",$A15))/GETPIVOTDATA("Sum of N total train",$A$5,"operator",$A15) -> 0.86993212 | P15: =1-(GETPIVOTDATA("Sum of N cancelled train (full + partial)",$A$5,"operator",$A15)+GETPIVOTDATA(P$4&"",$A$5,"operator",$A15))/GETPIVOTDATA("Sum of N total train",$A$5,"operator",$A15) -> 0.90270898 | Q15: =1-(GETPIVOTDATA("Sum of N cancelled train (full + partial)",$A$5,"operator",$A15)+GETPIVOTDATA(Q$4&"",$A$5,"operator",$A15))/GETPIVOTDATA("Sum of N total train",$A$5,"operator",$A15) -> 0.9537088 | R15: =1-(GETPIVOTDATA("Sum of N cancelled train (full + partial)",$A$5,"operator",$A15)+GETPIVOTDATA(R$4&"",$A$5,"operator",$A15))/GETPIVOTDATA("Sum of N total train",$A$5,"operator",$A15) -> 0.98673026
A16: NS | B16: 492374 | C16: 59374 | D16: 64066 | E16: 38832 | F16: 31818 | G16: 18001 | H16: 9730 | I16: 2574 | J16: 776 | K16: =GETPIVOTDATA("Sum of N cancelled train (full + partial)",$A$5,"operator",$A16)/GETPIVOTDATA("Sum of N total train",$A$5,"operator",$A16) -> 0.1205872 | L16: =1-(GETPIVOTDATA("Sum of N cancelled train (full + partial)",$A$5,"operator",$A16)+GETPIVOTDATA(L$4&"",$A$5,"operator",$A16))/GETPIVOTDATA("Sum of N total train",$A$5,"operator",$A16) -> 0.74929627 | M16: =1-(GETPIVOTDATA("Sum of N cancelled train (full + partial)",$A$5,"operator",$A16)+GETPIVOTDATA(M$4&"",$A$5,"operator",$A16))/GETPIVOTDATA("Sum of N total train",$A$5,"operator",$A16) -> 0.80054593 | N16: =1-(GETPIVOTDATA("Sum of N cancelled train (full + partial)",$A$5,"operator",$A16)+GETPIVOTDATA(N$4&"",$A$5,"operator",$A16))/GETPIVOTDATA("Sum of N total train",$A$5,"operator",$A16) -> 0.8147912 | O16: =1-(GETPIVOTDATA("Sum of N cancelled train (full + partial)",$A$5,"operator",$A16)+GETPIVOTDATA(O$4&"",$A$5,"operator",$A16))/GETPIVOTDATA("Sum of N total train",$A$5,"operator",$A16) -> 0.8428532 | P16: =1-(GETPIVOTDATA("Sum of N cancelled train (full + partial)",$A$5,"operator",$A16)+GETPIVOTDATA(P$4&"",$A$5,"operator",$A16))/GETPIVOTDATA("Sum of N total train",$A$5,"operator",$A16) -> 0.8596514 | Q16: =1-(GETPIVOTDATA("Sum of N cancelled train (full + partial)",$A$5,"operator",$A16)+GETPIVOTDATA(Q$4&"",$A$5,"operator",$A16))/GETPIVOTDATA("Sum of N total train",$A$5,"operator",$A16) -> 0.87418507 | R16: =1-(GETPIVOTDATA("Sum of N cancelled train (full + partial)",$A$5,"operator",$A16)+GETPIVOTDATA(R$4&"",$A$5,"operator",$A16))/GETPIVOTDATA("Sum of N total train",$A$5,"operator",$A16) -> 0.87783677
A17: OEBB | B17: 142919 | C17: 3356 | D17: 40422 | E17: 31087 | F17: 27951 | G17: 20342 | H17: 15406 | I17: 7261 | J17: 2421 | K17: =GETPIVOTDATA("Sum of N cancelled train (full + partial)",$A$5,"operator",$A17)/GETPIVOTDATA("Sum of N total train",$A$5,"operator",$A17) -> 0.023481832 | L17: =1-(GETPIVOTDATA("Sum of N cancelled train (full + partial)",$A$5,"operator",$A17)+GETPIVOTDATA(L$4&"",$A$5,"operator",$A17))/GETPIVOTDATA("Sum of N total train",$A$5,"operator",$A17) -> 0.69368663 | M17: =1-(GETPIVOTDATA("Sum of N cancelled train (full + partial)",$A$5,"operator",$A17)+GETPIVOTDATA(M$4&"",$A$5,"operator",$A17))/GETPIVOTDATA("Sum of N total train",$A$5,"operator",$A17) -> 0.75900335 | N17: =1-(GETPIVOTDATA("Sum of N cancelled train (full + partial)",$A$5,"operator",$A17)+GETPIVOTDATA(N$4&"",$A$5,"operator",$A17))/GETPIVOTDATA("Sum of N total train",$A$5,"operator",$A17) -> 0.78094585 | O17: =1-(GETPIVOTDATA("Sum of N cancelled train (full + partial)",$A$5,"operator",$A17)+GETPIVOTDATA(O$4&"",$A$5,"operator",$A17))/GETPIVOTDATA("Sum of N total train",$A$5,"operator",$A17) -> 0.8341858 | P17: =1-(GETPIVOTDATA("Sum of N cancelled train (full + partial)",$A$5,"operator",$A17)+GETPIVOTDATA(P$4&"",$A$5,"operator",$A17))/GETPIVOTDATA("Sum of N total train",$A$5,"operator",$A17) -> 0.86872284 | Q17: =1-(GETPIVOTDATA("Sum of N cancelled train (full + partial)",$A$5,"operator",$A17)+GETPIVOTDATA(Q$4&"",$A$5,"operator",$A17))/GETPIVOTDATA("Sum of N total train",$A$5,"operator",$A17) -> 0.92571317 | R17: =1-(GETPIVOTDATA("Sum of N cancelled train (full + partial)",$A$5,"operator",$A17)+GETPIVOTDATA(R$4&"",$A$5,"operator",$A17))/GETPIVOTDATA("Sum of N total train",$A$5,"operator",$A17) -> 0.9595785
... A29: ZSSK | B29: 1535 | C29: 2 | D29: 184 | E29: 151 | F29: 141 | G29: 108 | H29: 86 | I29: 50 | J29: 20 | K29: =GETPIVOTDATA("Sum of N cancelled train (full + partial)",$A$5,"operator",$A29)/GETPIVOTDATA("Sum of N total train",$A$5,"operator",$A29) -> 0.0013029316 | L29: =1-(GETPIVOTDATA("Sum of N cancelled train (full + partial)",$A$5,"operator",$A29)+GETPIVOTDATA(L$4&"",$A$5,"operator",$A29))/GETPIVOTDATA("Sum of N total train",$A$5,"operator",$A29) -> 0.87882736 | M29: =1-(GETPIVOTDATA("Sum of N cancelled train (full + partial)",$A$5,"operator",$A29)+GETPIVOTDATA(M$4&"",$A$5,"operator",$A29))/GETPIVOTDATA("Sum of N total train",$A$5,"operator",$A29) -> 0.90032573 | N29: =1-(GETPIVOTDATA("Sum of N cancelled train (full + partial)",$A$5,"operator",$A29)+GETPIVOTDATA(N$4&"",$A$5,"operator",$A29))/GETPIVOTDATA("Sum of N total train",$A$5,"operator",$A29) -> 0.90684039 | O29: =1-(GETPIVOTDATA("Sum of N cancelled train (full + partial)",$A$5,"operator",$A29)+GETPIVOTDATA(O$4&"",$A$5,"operator",$A29))/GETPIVOTDATA("Sum of N total train",$A$5,"operator",$A29) -> 0.92833876 | P29: =1-(GETPIVOTDATA("Sum of N cancelled train (full + partial)",$A$5,"operator",$A29)+GETPIVOTDATA(P$4&"",$A$5,"operator",$A29))/GETPIVOTDATA("Sum of N total train",$A$5,"operator",$A29) -> 0.94267101 | Q29: =1-(GETPIVOTDATA("Sum of N cancelled train (full + partial)",$A$5,"operator",$A29)+GETPIVOTDATA(Q$4&"",$A$5,"operator",$A29))/GETPIVOTDATA("Sum of N total train",$A$5,"operator",$A29) -> 0.96612378 | R29: =1-(GETPIVOTDATA("Sum of N cancelled train (full + partial)",$A$5,"operator",$A29)+GETPIVOTDATA(R$4&"",$A$5,"operator",$A29))/GETPIVOTDATA("Sum of N total train",$A$5,"operator",$A29) -> 0.98566775
A30: Grand Total | B30: 2228526 | C30: 128592 | D30: 536315 | E30: 406279 | F30: 370587 | G30: 267442 | H30: 196975 | I30: 94466 | J30: 30914
A35: Journey type | B35: (Multiple Items)
A36: Long distance | B36: Yes
A38: Row Labels | B38: Sum of N total train | C38: Sum of N cancelled train (full + partial) | D38: Sum of N train delay (> 3 min) | E38: Sum of N train delay (> 5 min) | F38: Sum of N train delay (> 6 min) | G38: Sum of N train delay (> 10 min) | H38: Sum of N train delay (> 15 min) | I38: Sum of N train delay (> 30 min) | J38: Sum of N train delay (> 60 min) | K38: Sum of N train arriving at terminus
A39: Westbahn | B39: 20917 | C39: 126 | D39: 2268 | E39: 1736 | F39: 1542 | G39: 1006 | H39: 619 | I39: 244 | J39: 68 | K39: 20633
A40: Grand Total | B40: 20917 | C40: 126 | D40: 2268 | E40: 1736 | F40: 1542 | G40: 1006 | H40: 619 | I40: 244 | J40: 68 | K40: 20633

Sheet Summary
A1: Year | B1: Month | C1: operator | D1: Punctuality scope | E1: Route type | F1: Journey type | G1: HSR service | H1: Long distance | I1: Night train | J1: N total train | K1: N cancelled train (full cancellation) | L1: N cancelled train (partial cancellation) | M1: N cancelled train (full + partial) | N1: N train delay (> 3 min) | O1: N train delay (> 5 min) | P1: N train delay (> 6 min) | Q1: N train delay (> 10 min) | R1: N train delay (> 15 min) | S1: N train delay (> 30 min) | T1: N train delay (> 60 min) | U1: N train arriving at terminus
A2: 2025 | B2: 1 | C2: CFL | D2: national network | E2: IC | F2: international | G2: No | H2: Yes | I2: No | J2: 1182 | K2: 10 | L2: 0 | M2: 10 | N2: 198 | O2: 105 | P2: 84 | Q2: 54 | R2: 36 | S2: 10 | T2: 0 | U2: 1172
A3: 2025 | B3: 1 | C3: CFL | D3: national network | E3: TGV INOUI | F3: domestic | G3: Yes | H3: Yes | I3: No | J3: 1 | K3: 0 | L3: 1 | M3: 1 | N3: 0 | O3: 0 | P3: 0 | Q3: 0 | R3: 0 | S3: 0 | T3: 0 | U3: 1
A4: 2025 | B4: 1 | C4: CFL | D4: national network | E4: TGV INOUI | F4: international | G4: Yes | H4: Yes | I4: No | J4: 64 | K4: 2 | L4: 0 | M4: 2 | N4: 35 | O4: 14 | P4: 14 | Q4: 12 | R4: 6 | S4: 1 | T4: 0 | U4: 62
A5: 2025 | B5: 1 | C5: CFL | D5: national network | E5: TGV INOUI | F5: unknown | G5: Yes | H5: Yes | I5: No | J5: 3 | K5: 0 | L5: 0 | M5: 0 | N5: 0 | O5: 0 | P5: 0 | Q5: 0 | R5: 0 | S5: 0 | T5: 0 | U5: 0
A6: 2025 | B6: 1 | C6: CFR | D6: national network | E6: D | F6: international | G6: No | H6: No | I6: No | J6: 26 | K6: 0 | L6: 0 | M6: 0 | N6: 1 | O6: 1 | P6: 1 | Q6: 0 | R6: 0 | S6: 0 | T6: 0 | U6: 26
A7: 2025 | B7: 1 | C7: CFR | D7: national network | E7: EC | F7: international | G7: No | H7: No | I7: No | J7: 22 | K7: 0 | L7: 0 | M7: 0 | N7: 0 | O7: 0 | P7: 0 | Q7: 0 | R7: 0 | S7: 0 | T7: 0 | U7: 7
A8: 2025 | B8: 1 | C8: CFR | D8: national network | E8: EC | F8: international | G8: No | H8: Yes | I8: No | J8: 7 | K8: 0 | L8: 0 | M8: 0 | N8: 0 | O8: 0 | P8: 0 | Q8: 0 | R8: 0 | S8: 0 | T8: 0 | U8: 7
A9: 2025 | B9: 1 | C9: Ceske Drahy | D9: national network | E9: EC | F9: domestic | G9: No | H9: No | I9: No | J9: 3 | K9: 0 | L9: 0 | M9: 0 | N9: 0 | O9: 0 | P9: 0 | Q9: 0 | R9: 0 | S9: 0 | T9: 0 | U9: 3
A10: 2025 | B10: 1 | C10: Ceske Drahy | D10: national network | E10: EC | F10: international | G10: No | H10: No | I10: No | J10: 810 | K10: 0 | L10: 0 | M10: 0 | N10: 108 | O10: 88 | P10: 87 | Q10: 58 | R10: 37 | S10: 12 | T10: 4 | U10: 781
A11: 2025 | B11: 1 | C11: Ceske Drahy | D11: national network | E11: EC | F11: unknown | G11: No | H11: No | I11: No | J11: 3 | K11: 0 | L11: 0 | M11: 0 | N11: 0 | O11: 0 | P11: 0 | Q11: 0 | R11: 0 | S11: 0 | T11: 0 | U11: 0
A12: 2025 | B12: 1 | C12: Ceske Drahy | D12: national network | E12: EN | F12: domestic | G12: No | H12: Yes | I12: Yes | J12: 5 | K12: 0 | L12: 0 | M12: 0 | N12: 1 | O12: 1 | P12: 1 | Q12: 1 | R12: 1 | S12: 1 | T12: 0 | U12: 5
A13: 2025 | B13: 1 | C13: Ceske Drahy | D13: national network | E13: EN | F13: international | G13: No | H13: Yes | I13: Yes | J13: 201 | K13: 0 | L13: 1 | M13: 1 | N13: 40 | O13: 36 | P13: 34 | Q13: 23 | R13: 14 | S13: 10 | T13: 4 | U13: 163
... A213: 2025 | B213: 1 | C213: UNKNOWN_OPERATOR | D213: national network | E213: UEX | F213: international | G213: No | H213: No | I213: No | J213: 6 | K213: 0 | L213: 0 | M213: 0 | N213: 1 | O213: 1 | P213: 1 | Q213: 1 | R213: 0 | S213: 0 | T213: 0 | U213: 6
A214: 2025 | B214: 1 | C214: UNKNOWN_OPERATOR | D214: national network | F214: domestic | G214: No | H214: No | I214: No | J214: 17 | K214: 2 | L214: 1 | M214: 3 | N214: 6 | O214: 5 | P214: 5 | Q214: 5 | R214: 2 | S214: 1 | T214: 1 | U214: 15
A215: 2025 | B215: 1 | C215: UZ | D215: national network | E215: D | F215: international | G215: No | H215: No | I215: No | J215: 19 | K215: 0 | L215: 0 | M215: 0 | N215: 0 | O215: 0 | P215: 0 | Q215: 0 | R215: 0 | S215: 0 | T215: 0 | U215: 19
A216: 2025 | B216: 1 | C216: Westbahn | D216: whole journey | E216: WB | F216: domestic | G216: No | H216: Yes | I216: No | J216: 1385 | K216: 0 | L216: 0 | M216: 0 | N216: 16 | O216: 13 | P216: 12 | Q216: 7 | R216: 4 | S216: 3 | T216: 0 | U216: 1110
A217: 2025 | B217: 1 | C217: Westbahn | D217: whole journey | E217: WB | F217: international | G217: No | H217: Yes | I217: No | J217: 363 | K217: 0 | L217: 10 | M217: 10 | N217: 138 | O217: 102 | P217: 85 | Q217: 47 | R217: 22 | S217: 6 | T217: 2 | U217: 363
A218: 2025 | B218: 1 | C218: ZSSK | D218: national network | E218: EC | F218: international | G218: No | H218: No | I218: No | J218: 68 | K218: 0 | L218: 0 | M218: 0 | N218: 5 | O218: 5 | P218: 4 | Q218: 3 | R218: 2 | S218: 0 | T218: 0 | U218: 68
A219: 2025 | B219: 1 | C219: ZSSK | D219: national network | E219: EN | F219: international | G219: No | H219: Yes | I219: Yes | J219: 87 | K219: 0 | L219: 0 | M219: 0 | N219: 0 | O219: 0 | P219: 0 | Q219: 0 | R219: 0 | S219: 0 | T219: 0 | U219: 49
A220: 2025 | B220: 1 | C220: ZSSK | D220: national network | E220: NJ | F220: international | G220: No | H220: Yes | I220: Yes | J220: 6 | K220: 0 | L220: 0 | M220: 0 | N220: 0 | O220: 0 | P220: 0 | Q220: 0 | R220: 0 | S220: 0 | T220: 0 | U220: 0
A221: 2025 | B221: 1 | C221: ZSSK | D221: national network | E221: RJX | F221: international | G221: Yes | H221: Yes | I221: No | J221: 45 | K221: 0 | L221: 0 | M221: 0 | N221: 2 | O221: 1 | P221: 1 | Q221: 1 | R221: 1 | S221: 0 | T221: 0 | U221: 45
A222: 2025 | B222: 2 | C222: CFL | D222: national network | E222: IC | F222: international | G222: No | H222: Yes | I222: No | J222: 809 | K222: 8 | L222: 0 | M222: 8 | N222: 161 | O222: 92 | P222: 69 | Q222: 43 | R222: 29 | S222: 8 | T222: 0 | U222: 801
A223: 2025 | B223: 2 | C223: CFL | D223: national network | E223: TGV INOUI | F223: international | G223: Yes | H223: Yes | I223: No | J223: 68 | K223: 0 | L223: 0 | M223: 0 | N223: 39 | O223: 21 | P223: 21 | Q223: 19 | R223: 12 | S223: 5 | T223: 3 | U223: 68
A224: 2025 | B224: 2 | C224: CFL | D224: national network | E224: TGV INOUI | F224: unknown | G224: Yes | H224: Yes | I224: No | J224: 4 | K224: 0 | L224: 0 | M224: 0 | N224: 0 | O224: 0 | P224: 0 | Q224: 0 | R224: 0 | S224: 0 | T224: 0 | U224: 0
A225: 2025 | B225: 2 | C225: CFR | D225: national network | E225: D | F225: international | G225: No | H225: No | I225: No | J225: 54 | K225: 0 | L225: 0 | M225: 0 | N225: 1 | O225: 1 | P225: 1 | Q225: 0 | R225: 0 | S225: 0 | T225: 0 | U225: 54
A226: 2025 | B226: 2 | C226: Ceske Drahy | D226: national network | E226: EC | F226: international | G226: No | H226: No | I226: No | J226: 876 | K226: 1 | L226: 0 | M226: 1 | N226: 128 | O226: 102 | P226: 92 | Q226: 64 | R226: 49 | S226: 24 | T226: 6 | U226: 875
... A399: 2025 | B399: 2 | C399: UNKNOWN_OPERATOR | D399: national network | E399: UEX | F399: international | G399: No | H399: No | I399: No | J399: 16 | K399: 0 | L399: 0 | M399: 0 | N399: 11 | O399: 9 | P399: 9 | Q399: 8 | R399: 8 | S399: 8 | T399: 2 | U399: 16
A400: 2025 | B400: 2 | C400: UNKNOWN_OPERATOR | D400: national network | F400: domestic | G400: No | H400: No | I400: No | J400: 15 | K400: 0 | L400: 0 | M400: 0 | N400: 7 | O400: 6 | P400: 4 | Q400: 4 | R400: 3 | S400: 1 | T400: 0 | U400: 15
A401: 2025 | B401: 2 | C401: UNKNOWN_OPERATOR | D401: national network | F401: international | G401: No | H401: No | I401: No | J401: 128 | K401: 62 | L401: 63 | M401: 125 | N401: 2 | O401: 2 | P401: 1 | Q401: 1 | R401: 1 | S401: 0 | T401: 0 | U401: 4
A402: 2025 | B402: 2 | C402: UZ | D402: national network | E402: D | F402: international | G402: No | H402: No | I402: No | J402: 54 | K402: 0 | L402: 0 | M402: 0 | N402: 0 | O402: 0 | P402: 0 | Q402: 0 | R402: 0 | S402: 0 | T402: 0 | U402: 54
A403: 2025 | B403: 2 | C403: Westbahn | D403: whole journey | E403: WB | F403: domestic | G403: No | H403: Yes | I403: No | J403: 1343 | K403: 0 | L403: 0 | M403: 0 | N403: 28 | O403: 21 | P403: 18 | Q403: 14 | R403: 9 | S403: 2 | T403: 0 | U403: 1343
A404: 2025 | B404: 2 | C404: Westbahn | D404: whole journey | E404: WB | F404: international | G404: No | H404: Yes | I404: No | J404: 336 | K404: 0 | L404: 9 | M404: 9 | N404: 171 | O404: 118 | P404: 103 | Q404: 49 | R404: 23 | S404: 9 | T404: 2 | U404: 332
A405: 2025 | B405: 2 | C405: ZSSK | D405: national network | E405: EC | F405: international | G405: No | H405: No | I405: No | J405: 71 | K405: 0 | L405: 0 | M405: 0 | N405: 5 | O405: 4 | P405: 4 | Q405: 3 | R405: 2 | S405: 1 | T405: 0 | U405: 71
A406: 2025 | B406: 2 | C406: ZSSK | D406: national network | E406: EN | F406: international | G406: No | H406: Yes | I406: Yes | J406: 52 | K406: 0 | L406: 0 | M406: 0 | N406: 1 | O406: 1 | P406: 1 | Q406: 1 | R406: 1 | S406: 1 | T406: 0 | U406: 52
A407: 2025 | B407: 2 | C407: ZSSK | D407: national network | E407: RJX | F407: international | G407: Yes | H407: Yes | I407: No | J407: 37 | K407: 0 | L407: 0 | M407: 0 | N407: 3 | O407: 3 | P407: 3 | Q407: 2 | R407: 1 | S407: 0 | T407: 0 | U407: 37
A408: 2025 | B408: 3 | C408: CFL | D408: national network | E408: IC | F408: international | G408: No | H408: Yes | I408: No | J408: 1032 | K408: 7 | L408: 5 | M408: 12 | N408: 157 | O408: 93 | P408: 77 | Q408: 42 | R408: 27 | S408: 9 | T408: 0 | U408: 1025
A409: 2025 | B409: 3 | C409: CFL | D409: national network | E409: TGV INOUI | F409: international | G409: Yes | H409: Yes | I409: No | J409: 61 | K409: 0 | L409: 0 | M409: 0 | N409: 34 | O409: 7 | P409: 7 | Q409: 6 | R409: 5 | S409: 3 | T409: 1 | U409: 61
A410: 2025 | B410: 3 | C410: CFL | D410: national network | E410: TGV INOUI | F410: unknown | G410: Yes | H410: Yes | I410: No | J410: 3 | K410: 0 | L410: 0 | M410: 0 | N410: 0 | O410: 0 | P410: 0 | Q410: 0 | R410: 0 | S410: 0 | T410: 0 | U410: 0
A411: 2025 | B411: 3 | C411: CFR | D411: national network | E411: D | F411: international | G411: No | H411: No | I411: No | J411: 62 | K411: 0 | L411: 0 | M411: 0 | N411: 1 | O411: 1 | P411: 1 | Q411: 1 | R411: 0 | S411: 0 | T411: 0 | U411: 62
...

Sheet Comp_chuuchuu
A1: Year | B1: Operator | C1: Services | D1: Threshold (min) | E1: Measurement | F1: Train or passenger punctuality | G1: Account cancellations | H1: Account joint services | I1: Chuuchuu/official | J1: Punctuality | K1: Same metric with Chuuchuu | L1: %pp diff | M1: Our own calculations or reliability | N1: Cancellations
A2: 2025 | B2: DB | C2: LD | D2: 6 | E2: At all stops | F2: Train punctuality | G2: No | H2: All collaborations on DE network | I2: Official | J2: 0.601 | K2: 0.5882 | L2: =J2-K2 -> 0.0128 | M2: / | N2: /
A3: 2025 | B3: DB | C3: LD | D3: 5 | E3: At all stops | F3: Train punctuality | G3: Yes | H3: All collaborations on DE network | I3: Chuuchuu | J3: / | K3: / | L3: / | M3: =INDEX(Table1[Reliability 5min],MATCH($B3,'Pivot table'!$A$6:$A$29,0)) -> 0.40041691 | N3: =INDEX(Table1[Cancellation rate],MATCH($B3,'Pivot table'!$A$6:$A$29,0)) -> 0.10879301
A4: 2025 | B4: Eurostar | C4: Routes Belgium | D4: 6 | E4: All network | F4: Train punctuality | G4: No | H4: To ask | I4: Official | J4: 0.8 | K4: 0.772 | L4: =J4-K4 -> 0.028 | M4: / | N4: /
A5: 2025 | B5: Eurostar | C5: London routes | D5: 5 | E5: Arriving at St pancras? | F5: Train punctuality | G5: Likely yes? | H5: To ask | I5: Official | J5: 0.731 | K5: 0.744 | L5: =J5-K5 -> -0.013 | M5: / | N5: /
A6: 2025 | B6: Eurostar | C6: London routes | D6: 15 | E6: Arriving at St pancras? | F6: Train punctuality | G6: Likely yes? | H6: To ask | I6: Official | J6: 0.833 | K6: 0.824 | L6: =J6-K6 -> 0.009 | M6: / | N6: /
A7: 2025 | B7: Eurostar | C7: Continental routes | D7: 15 | E7: All network (except St Pancras) | F7: Train punctuality | G7: Likely yes? | H7: To ask | I7: Official | J7: 0.781 | K7: 0.781 | L7: =J7-K7 -> 0 | M7: / | N7: /
A8: 2025 | B8: Eurostar | C8: All | D8: 5 | E8: Terminus | F8: Train punctuality | G8: Yes | H8: No | I8: Chuuchuu | J8: / | K8: / | L8: / | M8: =INDEX(Table1[Reliability 5min],MATCH($B8,'Pivot table'!$A$6:$A$29,0)) -> 0.64305637 | N8: =INDEX(Table1[Cancellation rate],MATCH($B8,'Pivot table'!$A$6:$A$29,0)) -> 0.10287121
A9: 2025 | B9: NS | C9: All | D9: 3 | E9: 47 different points on networks | F9: Pax punctuality | G9: Yes | H9: Yes (except ICE trains) | I9: Official | J9: 0.855 | K9: 0.865 | L9: =J9-K9 -> -0.01 | M9: / | N9: /
A10: 2025 | B10: NS | C10: All | D10: 10 | E10: 47 different points on networks | F10: Pax punctuality | G10: Yes | H10: Yes (except ICE trains) | I10: Official | J10: 0.953 | K10: 0.936 | L10: =J10-K10 -> 0.017 | M10: / | N10: /
A11: 2025 | B11: NS | C11: LD | D11: 5 | E11: Terminus | F11: Tain punctuality | G11: Yes | H11: Yes | I11: Chuuchuu | J11: / | K11: / | L11: / | M11: =INDEX(Table1[Reliability 5min],MATCH($B11,'Pivot table'!$A$6:$A$29,0)) -> 0.80054593 | N11: =INDEX(Table1[Cancellation rate],MATCH($B11,'Pivot table'!$A$6:$A$29,0)) -> 0.1205872
A12: 2025 | B12: OEBB | C12: LD | D12: 5min30 | E12: At all stops | F12: Train punctuality | G12: No | H12: Yes | I12: Official | J12: 0.816 | K12: 0.802 | L12: =J12-K12 -> 0.014 | M12: / | N12: /
A13: 2025 | B13: OEBB | C13: LD | D13: 5 | E13: At all stops | F13: Train punctuality | G13: Yes | H13: Yes | I13: Chuuchuu | J13: / | K13: / | L13: / | M13: =INDEX(Table1[Reliability 5min],MATCH($B13,'Pivot table'!$A$6:$A$29,0)) -> 0.75900335 | N13: =INDEX(Table1[Cancellation rate],MATCH($B13,'Pivot table'!$A$6:$A$29,0)) -> 0.023481832
A14: 2025 | B14: Ouigo - ART | C14: HSR | D14: 5 | E14: Terminus | F14: Train punctuality | G14: Not sure (here = no) | H14: / | I14: Official | J14: 0.725 | K14: 0.797 | L14: =J14-K14 -> -0.072 | M14: / | N14: /
A15: 2025 | B15: Ouigo - ART | C15: HSR | D15: 5 | E15: Terminus | F15: Train punctuality | G15: Not sure (here = yes) | H15: / | I15: Official | J15: 0.725 | K15: 0.787 | L15: =J15-K15 -> -0.062 | M15: / | N15: /
A16: 2025 | B16: Ouigo | C16: All | D16: 5 | E16: Terminus | F16: Train punctuality | G16: Yes | H16: / | I16: Chuuchuu | J16: / | K16: / | L16: / | M16: =INDEX(Table1[Reliability 5min],MATCH($B16,'Pivot table'!$A$6:$A$29,0)) -> 0.80234031 | N16: =INDEX(Table1[Cancellation rate],MATCH($B16,'Pivot table'!$A$6:$A$29,0)) -> 0.015320586
A17: 2025 | B17: SBB | C17: LD | D17: 3 | E17: At all stops | F17: Train punctuality | G17: Yes (short notice cancellations) | H17: Likely | I17: Official | J17: 0.9273 | K17: 0.953 | L17: =J17-K17 -> -0.0257 | M17: / | N17: /
A18: 2025 | B18: SBB | C18: LD | D18: 5 | E18: Terminus | F18: Train punctuality | G18: Yes | H18: Yes | I18: Chuuchuu | J18: / | K18: / | L18: / | M18: =INDEX(Table1[Reliability 5min],MATCH($B17,'Pivot table'!$A$6:$A$29,0)) -> 0.94336053 | N18: =INDEX(Table1[Cancellation rate],MATCH($B17,'Pivot table'!$A$6:$A$29,0)) -> 0.026046807
A19: 2025 | B19: SNCB | C19: All | D19: 6 | E19: Terminus + Bxl | F19: Train punctuality | G19: No | H19: ? | I19: Official | J19: 0.9172 | K19: 0.906 | L19: =J19-K19 -> 0.0112 | M19: / | N19: /
A20: 2025 | B20: SNCB | C20: IC | D20: 6 | E20: Terminus + Bxl | F20: Train punctuality | G20: No | H20: ? | I20: Official | J20: 0.8982 | K20: 0.889 | L20: =J20-K20 -> 0.0092 | M20: / | N20: /
A21: 2025 | B21: SNCB | C21: IC | D21: 5 | E21: Terminus | F21: Train punctuality | G21: Yes | H21: Yes | I21: Chuuchuu | J21: / | K21: / | L21: / | M21: =INDEX(Table1[Reliability 5min],MATCH($B20,'Pivot table'!$A$6:$A$29,0)) -> 0.85936692 | N21: =INDEX(Table1[Cancellation rate],MATCH($B20,'Pivot table'!$A$6:$A$29,0)) -> 0.020639185
A22: 2025 | B22: SNCF - ART | C22: TGV Inoui | D22: 5 | E22: Terminus | F22: Train punctuality | G22: Not sure (here = no) | H22: / | I22: Official | J22: 0.767 | K22: 0.745 | L22: =J22-K22 -> 0.022 | M22: / | N22: /
A23: 2025 | B23: SNCF - ART | C23: TGV Inoui | D23: 5 | E23: Terminus | F23: Train punctuality | G23: Not sure (here = yes) | H23: / | I23: Official | J23: 0.767 | K23: 0.739 | L23: =J23-K23 -> 0.028 | M23: / | N23: /
A24: 2025 | B24: SNCF | C24: TGV Inoui | D24: Composite | E24: Terminus | F24: Train punctuality | G24: Not sure (here = no) | H24: / | I24: Official | J24: 0.866 | K24: 0.856 | L24: =J24-K24 -> 0.01 | M24: / | N24: /
A25: 2025 | B25: SNCF - ART | C25: Intercités | D25: 5 | E25: Terminus | F25: Train punctuality | G25: Not sure (here = no) | H25: / | I25: Official | J25: 0.72 | K25: 0.684 | L25: =J25-K25 -> 0.036 | M25: / | N25: /
A26: 2025 | B26: SNCF - ART | C26: Intercités | D26: 5 | E26: Terminus | F26: Train punctuality | G26: Not sure (here = yes) | H26: / | I26: Official | J26: 0.72 | K26: 0.67 | L26: =J26-K26 -> 0.05 | M26: / | N26: /
A27: 2025 | B27: SNCF | C27: Intercités | D27: Composite | E27: Terminus | F27: Train punctuality | G27: Yes | H27: / | I27: Official | J27: 0.846 | K27: 0.81 | L27: =J27-K27 -> 0.036 | M27: / | N27: /
A28: 2025 | B28: SNCF | C28: All LD | D28: 5 | E28: Terminus | F28: Train punctuality | G28: Yes | H28: / | I28: Chuuchuu | J28: / | K28: / | L28: / | M28: =INDEX(Table1[Reliability 5min],MATCH($B28,'Pivot table'!$A$6:$A$29,0)) -> 0.84042496 | N28: =INDEX(Table1[Cancellation rate],MATCH($B28,'Pivot table'!$A$6:$A$29,0)) -> 0.011562631
A29: 2025 | B29: Trenitalia | C29: Frecce | D29: 10 | E29: Terminus? | F29: Train punctuality | G29: No? | H29: No | I29: Official | J29: 0.753 | K29: 0.755 | L29: =J29-K29 -> -0.002 | M29: / | N29: /
A30: 2025 | B30: Trenitalia | C30: All LD | D30: 5 | E30: Terminus | F30: Train punctuality | G30: Yes | H30: Yes | I30: Chuuchuu | J30: / | K30: / | L30: / | M30: =INDEX(Table1[Reliability 5min],MATCH($B30,'Pivot table'!$A$6:$A$29,0)) -> 0.63195077 | N30: =INDEX(Table1[Cancellation rate],MATCH($B30,'Pivot table'!$A$6:$A$29,0)) -> 0.020140865
A31: 2025 | B31: Trenitalia France | C31: Paris-Lyon | D31: 5 | E31: Terminus | F31: Train punctuality | G31: Not sure (here = no) | H31: / | I31: Official | J31: 0.835 | K31: 0.831 | L31: =J31-K31 -> 0.004 | M31: / | N31: /
A32: 2025 | B32: Trenitalia France | C32: Paris-Lyon | D32: 5 | E32: Terminus | F32: Train punctuality | G32: Not sure (here = yes) | H32: / | I32: Official | J32: 0.835 | K32: 0.831 | L32: =J32-K32 -> 0.004 | M32: / | N32: /
A33: 2025 | B33: Trenitalia France | C33: All | D33: 5 | E33: Terminus | F33: Train punctuality | G33: Yes | H33: / | I33: Chuuchuu | J33: / | K33: / | L33: / | M33: =INDEX(Table1[Reliability 5min],MATCH($B33,'Pivot table'!$A$6:$A$29,0)) -> 0.7573246 | N33: =INDEX(Table1[Cancellation rate],MATCH($B33,'Pivot table'!$A$6:$A$29,0)) -> 0.0053970702
A35: Penser a verifier données Intercités ART
A36: 2025 | B36: Westbahn | C36: All | D36: 5.5 | E36: Terminus | F36: Train punctuality | G36: Yes | H36: / | I36: Official | J36: 0.8344 | K36: 0.687 | L36: =J36-K36 -> 0.1474 | M36: =INDEX(Table1[Reliability 5min],MATCH($B36,'Pivot table'!$A$6:$A$29,0)) -> 0.9109815 | N36: =INDEX(Table1[Cancellation rate],MATCH($B36,'Pivot table'!$A$6:$A$29,0)) -> 0.0060238084
J38: Official | K38: Chuuchuu
B39: {=_xlfn._xlws.FILTER(B2:K33,J2:J33<>"/")} -> DB | C39: LD | D39: 6 | E39: At all stops | F39: Train punctuality | G39: No | H39: All collaborations on DE network | I39: Official | J39: 0.601 | K39: 0.5882
B40: Eurostar | C40: Routes Belgium | D40: 6 | E40: All network | F40: Train punctuality | G40: No | H40: To ask | I40: Official | J40: 0.8 | K40: 0.772
B41: Eurostar | C41: London routes | D41: 5 | E41: Arriving at St pancras? | F41: Train punctuality | G41: Likely yes? | H41: To ask | I41: Official | J41: 0.731 | K41: 0.744
B42: Eurostar | C42: London routes | D42: 15 | E42: Arriving at St pancras? | F42: Train punctuality | G42: Likely yes? | H42: To ask | I42: Official | J42: 0.833 | K42: 0.824
...

Sheet SNCF
A1: Year | B1: Month | C1: operator | D1: Punctuality scope | E1: Joint service | F1: Route type | G1: Journey type | H1: HSR service | I1: Long distance | J1: Night train | K1: N total train | L1: N cancelled train (full cancellation) | M1: N cancelled train (partial cancellation) | N1: N cancelled train (full + partial) | O1: N train delay (> 3 min) | P1: N train delay (> 5 min) | Q1: N train delay (> 6 min) | R1: N train delay (> 10 min) | S1: N train delay (> 15 min) | T1: N train delay (> 30 min) | U1: N train delay (> 60 min) | V1: N train arriving at terminus
A2: 2025 | B2: 1 | C2: SNCF | D2: national network | E2: DB_SNCF | F2: ICE | G2: international | H2: Yes | I2: Yes | J2: No | K2: 574 | L2: 15 | M2: 2 | N2: 17 | O2: 156 | P2: 103 | Q2: 102 | R2: 79 | S2: 62 | T2: 32 | U2: 8 | V2: 558
A3: 2025 | B3: 1 | C3: SNCF | D3: national network | E3: DB_SNCF | F3: TGV | G3: international | H3: Yes | I3: Yes | J3: No | K3: 113 | L3: 0 | M3: 0 | N3: 0 | O3: 24 | P3: 16 | Q3: 15 | R3: 8 | S3: 5 | T3: 3 | U3: 2 | V3: 113
A4: 2025 | B4: 1 | C4: SNCF | D4: national network | E4: DB_SNCF | F4: TGV INOUI | G4: international | H4: Yes | I4: Yes | J4: No | K4: 32 | L4: 0 | M4: 0 | N4: 0 | O4: 7 | P4: 4 | Q4: 4 | R4: 2 | S4: 2 | T4: 0 | U4: 0 | V4: 32
A5: 2025 | B5: 1 | C5: SNCF | D5: national network | E5: OEBB | F5: NJ | G5: international | H5: No | I5: Yes | J5: Yes | K5: 43 | L5: 2 | M5: 0 | N5: 2 | O5: 5 | P5: 5 | Q5: 5 | R5: 5 | S5: 5 | T5: 5 | U5: 1 | V5: 37
A6: 2025 | B6: 1 | C6: SNCF | D6: national network | E6: SBB_SNCF | F6: LYRIA | G6: domestic | H6: Yes | I6: Yes | J6: No | K6: 30 | L6: 0 | M6: 1 | N6: 1 | O6: 14 | P6: 11 | Q6: 11 | R6: 7 | S6: 5 | T6: 4 | U6: 1 | V6: 30
A7: 2025 | B7: 1 | C7: SNCF | D7: national network | E7: SBB_SNCF | F7: LYRIA | G7: international | H7: Yes | I7: Yes | J7: No | K7: 952 | L7: 0 | M7: 2 | N7: 2 | O7: 201 | P7: 126 | Q7: 126 | R7: 102 | S7: 85 | T7: 47 | U7: 21 | V7: 949
A8: 2025 | B8: 1 | C8: SNCF | D8: national network | E8: SBB_SNCF | F8: LYRIA | G8: unknown | H8: Yes | I8: Yes | J8: No | K8: 16 | L8: 0 | M8: 0 | N8: 0 | O8: 0 | P8: 0 | Q8: 0 | R8: 0 | S8: 0 | T8: 0 | U8: 0 | V8: 0
A9: 2025 | B9: 1 | C9: SNCF | D9: national network | E9: SNCB | F9: IC | G9: international | H9: No | I9: Yes | J9: No | K9: 1827 | L9: 4 | M9: 35 | N9: 39 | O9: 156 | P9: 97 | Q9: 75 | R9: 36 | S9: 15 | T9: 1 | U9: 0 | V9: 1823
A10: 2025 | B10: 1 | C10: SNCF | D10: national network | E10: SNCF | F10: ICE | G10: domestic | H10: Yes | I10: Yes | J10: No | K10: 1 | L10: 0 | M10: 0 | N10: 0 | O10: 1 | P10: 1 | Q10: 1 | R10: 0 | S10: 0 | T10: 0 | U10: 0 | V10: 1
A11: 2025 | B11: 1 | C11: SNCF | D11: national network | E11: SNCF | F11: ICE | G11: international | H11: Yes | I11: Yes | J11: No | K11: 26 | L11: 2 | M11: 0 | N11: 2 | O11: 13 | P11: 5 | Q11: 5 | R11: 4 | S11: 3 | T11: 1 | U11: 0 | V11: 24
A12: 2025 | B12: 1 | C12: SNCF | D12: national network | E12: SNCF | F12: ICE | G12: unknown | H12: Yes | I12: Yes | J12: No | K12: 2 | L12: 0 | M12: 0 | N12: 0 | O12: 0 | P12: 0 | Q12: 0 | R12: 0 | S12: 0 | T12: 0 | U12: 0 | V12: 0
A13: 2025 | B13: 1 | C13: SNCF | D13: national network | E13: SNCF | F13: INTERCITES | G13: domestic | H13: No | I13: Yes | J13: No | K13: 1687 | L13: 22 | M13: 38 | N13: 60 | O13: 543 | P13: 367 | Q13: 367 | R13: 279 | S13: 221 | T13: 144 | U13: 63 | V13: 1652
... A232: 2025 | B232: 11 | C232: SNCF | D232: national network | E232: SNCF | F232: TT | G232: unknown | H232: No | I232: No | J232: No | K232: 78 | L232: 0 | M232: 0 | N232: 0 | O232: 0 | P232: 0 | Q232: 0 | R232: 0 | S232: 0 | T232: 0 | U232: 0 | V232: 0
A233: 2025 | B233: 11 | C233: SNCF | D233: national network | E233: SNCF | G233: domestic | H233: No | I233: No | J233: No | K233: 15 | L233: 0 | M233: 0 | N233: 0 | O233: 0 | P233: 0 | Q233: 0 | R233: 0 | S233: 0 | T233: 0 | U233: 0 | V233: 15
A234: 2025 | B234: 11 | C234: SNCF | D234: national network | E234: SNCF | G234: unknown | H234: No | I234: No | J234: No | K234: 8 | L234: 0 | M234: 0 | N234: 0 | O234: 0 | P234: 0 | Q234: 0 | R234: 0 | S234: 0 | T234: 0 | U234: 0 | V234: 0
A235: 2025 | B235: 12 | C235: SNCF | D235: national network | E235: DB_SNCF | F235: ICE | G235: international | H235: Yes | I235: Yes | J235: No | K235: 669 | L235: 4 | M235: 4 | N235: 8 | O235: 252 | P235: 188 | Q235: 177 | R235: 144 | S235: 112 | T235: 51 | U235: 20 | V235: 663
A236: 2025 | B236: 12 | C236: SNCF | D236: national network | E236: DB_SNCF | F236: OUI | G236: international | H236: Yes | I236: Yes | J236: No | K236: 10 | L236: 0 | M236: 0 | N236: 0 | O236: 3 | P236: 2 | Q236: 2 | R236: 2 | S236: 1 | T236: 0 | U236: 0 | V236: 10
A237: 2025 | B237: 12 | C237: SNCF | D237: national network | E237: DB_SNCF | F237: TGV | G237: international | H237: Yes | I237: Yes | J237: No | K237: 99 | L237: 2 | M237: 1 | N237: 3 | O237: 46 | P237: 39 | Q237: 38 | R237: 33 | S237: 20 | T237: 7 | U237: 1 | V237: 97
A238: 2025 | B238: 12 | C238: SNCF | D238: national network | E238: DB_SNCF | F238: TGV INOUI | G238: international | H238: Yes | I238: Yes | J238: No | K238: 34 | L238: 0 | M238: 0 | N238: 0 | O238: 5 | P238: 2 | Q238: 2 | R238: 0 | S238: 0 | T238: 0 | U238: 0 | V238: 34
A239: 2025 | B239: 12 | C239: SNCF | D239: national network | E239: OEBB | F239: NJ | G239: international | H239: No | I239: Yes | J239: Yes | K239: 12 | L239: 0 | M239: 2 | N239: 2 | O239: 2 | P239: 2 | Q239: 2 | R239: 2 | S239: 0 | T239: 0 | U239: 0 | V239: 10
A240: 2025 | B240: 12 | C240: SNCF | D240: national network | E240: SBB_SNCF | F240: LYR | G240: international | H240: Yes | I240: Yes | J240: No | K240: 93 | L240: 0 | M240: 1 | N240: 1 | O240: 21 | P240: 11 | Q240: 11 | R240: 11 | S240: 6 | T240: 2 | U240: 0 | V240: 93
A241: 2025 | B241: 12 | C241: SNCF | D241: national network | E241: SBB_SNCF | F241: LYRIA | G241: domestic | H241: Yes | I241: Yes | J241: No | K241: 25 | L241: 0 | M241: 0 | N241: 0 | O241: 25 | P241: 25 | Q241: 25 | R241: 23 | S241: 20 | T241: 13 | U241: 3 | V241: 25
A242: 2025 | B242: 12 | C242: SNCF | D242: national network | E242: SBB_SNCF | F242: LYRIA | G242: international | H242: Yes | I242: Yes | J242: No | K242: 843 | L242: 0 | M242: 0 | N242: 0 | O242: 76 | P242: 38 | Q242: 36 | R242: 32 | S242: 28 | T242: 13 | U242: 2 | V242: 843
A243: 2025 | B243: 12 | C243: SNCF | D243: national network | E243: SBB_SNCF | F243: LYRIA | G243: unknown | H243: Yes | I243: Yes | J243: No | K243: 9 | L243: 0 | M243: 0 | N243: 0 | O243: 0 | P243: 0 | Q243: 0 | R243: 0 | S243: 0 | T243: 0 | U243: 0 | V243: 0
A244: 2025 | B244: 12 | C244: SNCF | D244: national network | E244: SNCB | F244: IC | G244: international | H244: No | I244: Yes | J244: No | K244: 785 | L244: 6 | M244: 0 | N244: 6 | O244: 2 | P244: 2 | Q244: 2 | R244: 1 | S244: 1 | T244: 1 | U244: 0 | V244: 779
A245: 2025 | B245: 12 | C245: SNCF | D245: national network | E245: SNCB_SNCF | F245: IC | G245: international | H245: No | I245: Yes | J245: No | K245: 4 | L245: 0 | M245: 0 | N245: 0 | O245: 3 | P245: 0 | Q245: 0 | R245: 0 | S245: 0 | T245: 0 | U245: 0 | V245: 4
A246: 2025 | B246: 12 | C246: SNCF | D246: national network | E246: SNCB_SNCF | F246: TER | G246: international | H246: No | I246: No | J246: No | K246: 327 | L246: 0 | M246: 1 | N246: 1 | O246: 51 | P246: 11 | Q246: 11 | R246: 6 | S246: 1 | T246: 0 | U246: 0 | V246: 327
... A289: 2025 | B289: 12 | C289: SNCF | D289: national network | E289: Trenitalia | F289: EXP | G289: international | H289: No | I289: Yes | J289: No | K289: 2 | L289: 2 | M289: 0 | N289: 2 | O289: 0 | P289: 0 | Q289: 0 | R289: 0 | S289: 0 | T289: 0 | U289: 0 | V289: 0

Sheet DB
A1: Year | B1: Month | C1: operator | D1: Punctuality scope | E1: Joint service | F1: Route type | G1: Journey type | H1: HSR service | I1: Long distance | J1: Night train | K1: N total train | L1: N cancelled train (full cancellation) | M1: N cancelled train (partial cancellation) | N1: N cancelled train (full + partial) | O1: N train delay (> 3 min) | P1: N train delay (> 5 min) | Q1: N train delay (> 6 min) | R1: N train delay (> 10 min) | S1: N train delay (> 15 min) | T1: N train delay (> 30 min) | U1: N train delay (> 60 min) | V1: N train arriving at terminus
A2: 2025 | B2: 1 | C2: DB | D2: national network | E2: Ceske Drahy | F2: EN | G2: international | H2: No | I2: Yes | J2: Yes | K2: 12 | L2: 0 | M2: 0 | N2: 0 | O2: 4 | P2: 2 | Q2: 2 | R2: 2 | S2: 2 | T2: 2 | U2: 1 | V2: 12
A3: 2025 | B3: 1 | C3: DB | D3: national network | E3: Ceske Drahy_DB | F3: EC | G3: international | H3: No | I3: Yes | J3: No | K3: 299 | L3: 2 | M3: 12 | N3: 14 | O3: 85 | P3: 59 | Q3: 52 | R3: 36 | S3: 26 | T3: 10 | U3: 5 | V3: 293
A4: 2025 | B4: 1 | C4: DB | D4: national network | E4: Ceske Drahy_DB | F4: EN | G4: international | H4: No | I4: Yes | J4: Yes | K4: 2 | L4: 0 | M4: 0 | N4: 0 | O4: 0 | P4: 0 | Q4: 0 | R4: 0 | S4: 0 | T4: 0 | U4: 0 | V4: 2
A5: 2025 | B5: 1 | C5: DB | D5: national network | E5: Ceske Drahy_DB_MAV | F5: EC | G5: international | H5: No | I5: Yes | J5: No | K5: 8 | L5: 0 | M5: 0 | N5: 0 | O5: 2 | P5: 2 | Q5: 1 | R5: 1 | S5: 1 | T5: 0 | U5: 0 | V5: 8
A6: 2025 | B6: 1 | C6: DB | D6: national network | E6: Ceske Drahy_DB_MAV_ZSSK | F6: EC | G6: international | H6: No | I6: Yes | J6: No | K6: 52 | L6: 0 | M6: 4 | N6: 4 | O6: 19 | P6: 16 | Q6: 15 | R6: 10 | S6: 9 | T6: 4 | U6: 1 | V6: 50
A7: 2025 | B7: 1 | C7: DB | D7: national network | E7: Ceske Drahy_DB_MAV_ZSSK | F7: EN | G7: international | H7: No | I7: Yes | J7: Yes | K7: 48 | L7: 2 | M7: 0 | N7: 2 | O7: 12 | P7: 11 | Q7: 10 | R7: 9 | S7: 7 | T7: 2 | U7: 1 | V7: 43
A8: 2025 | B8: 1 | C8: DB | D8: national network | E8: Ceske Drahy_DB_OEBB | F8: RJ | G8: international | H8: No | I8: Yes | J8: No | K8: 60 | L8: 1 | M8: 5 | N8: 6 | O8: 13 | P8: 9 | Q8: 9 | R8: 6 | S8: 6 | T8: 2 | U8: 1 | V8: 54
A9: 2025 | B9: 1 | C9: DB | D9: national network | E9: Ceske Drahy_DB_OEBB_PKP | F9: EN | G9: domestic | H9: No | I9: Yes | J9: Yes | K9: 5 | L9: 0 | M9: 0 | N9: 0 | O9: 4 | P9: 4 | Q9: 4 | R9: 4 | S9: 3 | T9: 0 | U9: 0 | V9: 5
A10: 2025 | B10: 1 | C10: DB | D10: national network | E10: Ceske Drahy_DB_OEBB_PKP | F10: EN | G10: international | H10: No | I10: Yes | J10: Yes | K10: 7 | L10: 0 | M10: 0 | N10: 0 | O10: 1 | P10: 0 | Q10: 0 | R10: 0 | S10: 0 | T10: 0 | U10: 0 | V10: 7
A11: 2025 | B11: 1 | C11: DB | D11: national network | E11: Ceske Drahy_DB_OEBB_PKP | F11: IC | G11: international | H11: No | I11: Yes | J11: No | K11: 14 | L11: 0 | M11: 0 | N11: 0 | O11: 6 | P11: 5 | Q11: 5 | R11: 3 | S11: 3 | T11: 1 | U11: 1 | V11: 14
A12: 2025 | B12: 1 | C12: DB | D12: national network | E12: Ceske Drahy_DB_PKP | F12: EN | G12: international | H12: No | I12: Yes | J12: Yes | K12: 30 | L12: 0 | M12: 1 | N12: 1 | O12: 13 | P12: 11 | Q12: 9 | R12: 6 | S12: 4 | T12: 2 | U12: 0 | V12: 30
A13: 2025 | B13: 1 | C13: DB | D13: national network | E13: Ceske Drahy_DB_SBB | F13: EC | G13: international | H13: No | I13: Yes | J13: No | K13: 58 | L13: 0 | M13: 0 | N13: 0 | O13: 19 | P13: 16 | Q13: 14 | R13: 12 | S13: 10 | T13: 6 | U13: 4 | V13: 58
... A688: 2025 | B688: 12 | C688: DB | D688: national network | E688: SNCF | F688: TGV INOUI | G688: international | H688: Yes | I688: Yes | J688: No | K688: 3 | L688: 0 | M688: 0 | N688: 0 | O688: 2 | P688: 2 | Q688: 2 | R688: 2 | S688: 2 | T688: 0 | U688: 0 | V688: 3

Sheet NS
A1: Year | B1: Month | C1: operator | D1: Punctuality scope | E1: Joint service | F1: Route type | G1: Journey type | H1: HSR service | I1: Long distance | J1: Night train | K1: N total train | L1: N cancelled train (full cancellation) | M1: N cancelled train (partial cancellation) | N1: N cancelled train (full + partial) | O1: N train delay (> 3 min) | P1: N train delay (> 5 min) | Q1: N train delay (> 6 min) | R1: N train delay (> 10 min) | S1: N train delay (> 15 min) | T1: N train delay (> 30 min) | U1: N train delay (> 60 min) | V1: N train arriving at terminus
A2: 2025 | B2: 1 | C2: NS | D2: national network | E2: DB | F2: IC | G2: international | H2: No | I2: Yes | J2: No | K2: 390 | L2: 36 | M2: 5 | N2: 41 | O2: 159 | P2: 148 | Q2: 142 | R2: 132 | S2: 102 | T2: 53 | U2: 13 | V2: 349
A3: 2025 | B3: 1 | C3: NS | D3: national network | E3: DB | F3: ICE | G3: domestic | H3: Yes | I3: Yes | J3: No | K3: 1 | L3: 0 | M3: 0 | N3: 0 | O3: 0 | P3: 0 | Q3: 0 | R3: 0 | S3: 0 | T3: 0 | U3: 0 | V3: 1
A4: 2025 | B4: 1 | C4: NS | D4: national network | E4: DB_NS | F4: ICE | G4: international | H4: Yes | I4: Yes | J4: No | K4: 447 | L4: 0 | M4: 7 | N4: 7 | O4: 169 | P4: 153 | Q4: 149 | R4: 138 | S4: 110 | T4: 46 | U4: 8 | V4: 444
A5: 2025 | B5: 1 | C5: NS | D5: national network | E5: DB_SBB | F5: IC | G5: international | H5: No | I5: Yes | J5: No | K5: 31 | L5: 0 | M5: 1 | N5: 1 | O5: 12 | P5: 11 | Q5: 11 | R5: 11 | S5: 8 | T5: 4 | U5: 0 | V5: 31
A6: 2025 | B6: 1 | C6: NS | D6: national network | E6: NS | F6: IC | G6: domestic | H6: No | I6: Yes | J6: No | K6: 36369 | L6: 0 | M6: 4032 | N6: 4032 | O6: 4646 | P6: 2464 | Q6: 1951 | R6: 953 | S6: 416 | T6: 42 | U6: 4 | V6: 33189
A7: 2025 | B7: 1 | C7: NS | D7: national network | E7: NS | F7: IC | G7: unknown | H7: No | I7: Yes | J7: No | K7: 1 | L7: 0 | M7: 0 | N7: 0 | O7: 0 | P7: 0 | Q7: 0 | R7: 0 | S7: 0 | T7: 0 | U7: 0 | V7: 0
A8: 2025 | B8: 1 | C8: NS | D8: national network | E8: NS | F8: ICD | G8: domestic | H8: No | I8: Yes | J8: No | K8: 3640 | L8: 0 | M8: 931 | N8: 931 | O8: 508 | P8: 328 | Q8: 276 | R8: 169 | S8: 74 | T8: 9 | U8: 1 | V8: 2943
A9: 2025 | B9: 1 | C9: NS | D9: national network | E9: NS | F9: NT | G9: domestic | H9: No | I9: Yes | J9: Yes | K9: 8 | L9: 0 | M9: 0 | N9: 0 | O9: 6 | P9: 4 | Q9: 3 | R9: 3 | S9: 2 | T9: 0 | U9: 0 | V9: 8
A10: 2025 | B10: 1 | C10: NS | D10: national network | E10: NS | F10: S | G10: domestic | H10: No | I10: No | J10: No | K10: 4191 | L10: 0 | M10: 50 | N10: 50 | O10: 338 | P10: 173 | Q10: 131 | R10: 57 | S10: 27 | T10: 1 | U10: 0 | V10: 4145
A11: 2025 | B11: 1 | C11: NS | D11: national network | E11: NS | F11: S | G11: international | H11: No | I11: No | J11: No | K11: 6 | L11: 5 | M11: 1 | N11: 6 | O11: 0 | P11: 0 | Q11: 0 | R11: 0 | S11: 0 | T11: 0 | U11: 0 | V11: 0
A12: 2025 | B12: 1 | C12: NS | D12: national network | E12: NS | F12: SPR | G12: domestic | H12: No | I12: No | J12: No | K12: 77886 | L12: 0 | M12: 3998 | N12: 3998 | O12: 5630 | P12: 2665 | Q12: 1981 | R12: 817 | S12: 317 | T12: 23 | U12: 0 | V12: 74806
A13: 2025 | B13: 1 | C13: NS | D13: national network | E13: NS | F13: ST | G13: domestic | H13: No | I13: No | J13: No | K13: 40640 | L13: 0 | M13: 1124 | N13: 1124 | O13: 3027 | P13: 1109 | Q13: 757 | R13: 276 | S13: 118 | T13: 8 | U13: 0 | V13: 39793
... A164: 2025 | B164: 12 | C164: NS | D164: national network | E164: OEBB | F164: NJ | G164: international | H164: No | I164: Yes | J164: Yes | K164: 186 | L164: 5 | M164: 0 | N164: 5 | O164: 104 | P164: 87 | Q164: 82 | R164: 68 | S164: 57 | T164: 43 | U164: 20 | V164: 181

Sheet OEBB
